package com.lyf.coroutine.exceptionsupervisor

import kotlinx.coroutines.*
import java.io.IOException

fun main() = runBlocking<Unit> {
    //region异常的传播
    /*val job = GlobalScope.launch { //launch根协程
        println("Throwing exception from launch")
        throw IndexOutOfBoundsException() //我们将在控制台打印 Thread.defaultUncaughtExceptionHandler
    }
    job.join()
    println("Joined failed job")

    val deferred = GlobalScope.async { //async根协程
        println("Throwing exception from async") //没有打印任何东西，依赖用户去调用await
        throw ArithmeticException()
    }
    try {
        deferred.await()
        println("Unreached")
    } catch (e: Exception) {
        println("Caught ArithmeticException")
    }*/
    //endregion

    //region CoroutineExceptionHandler
    /*val handler = CoroutineExceptionHandler { _, exception ->
        println("CoroutineExceptionHandler got $exception")
    }
    val job = GlobalScope.launch(handler) { // root coroutine, running in GlobalScope
        throw AssertionError()
    }
    val deferred = GlobalScope.async(handler) { // also root, but async instead of launch
        throw ArithmeticException() // Nothing will be printed, relying on user to call deferred.await()
    }
    joinAll(job, deferred)*/
    //endregion

    //region取消与异常
    /*val job = launch {
        val child = launch {
            try {
                delay(Long.MAX_VALUE)
            } finally {
                println("Child is cancelled")
            }
        }
        yield()
        println("Cancelling child")
        child.cancel()
        child.join()
        yield()
        println("Parent is not cancelled")
    }
    job.join()*/

    /*val handler = CoroutineExceptionHandler { _, exception ->
        println("CoroutineExceptionHandler got $exception")
    }
    val job = GlobalScope.launch(handler) {
        launch { // the first child
            try {
                delay(Long.MAX_VALUE)
            } finally {
                withContext(NonCancellable) {
                    println("Children are cancelled, but exception is not handled until all children terminate")
                    delay(100)
                    println("The first child finished its non cancellable block")
                }
            }
        }
        launch { // the second child
            delay(10)
            println("Second child throws an exception")
            throw ArithmeticException()
        }
    }
    job.join()*/
    //endregion

    //region异常聚合
    /*val handler = CoroutineExceptionHandler { _, exception ->
        println("CoroutineExceptionHandler got $exception with suppressed ${exception.suppressed.contentToString()}")
    }
    val job = GlobalScope.launch(handler) {
        launch {
            try {
                delay(Long.MAX_VALUE) // it gets cancelled when another sibling fails with IOException
            } finally {
                throw ArithmeticException() // the second exception
            }
        }
        launch {
            delay(100)
            throw IOException() // the first exception
        }
        delay(Long.MAX_VALUE)
    }
    job.join()*/

    /*val handler = CoroutineExceptionHandler { _, exception ->
        println("CoroutineExceptionHandler got $exception")
    }
    val job = GlobalScope.launch(handler) {
        val inner = launch { // all this stack of coroutines will get cancelled
            launch {
                launch {
                    throw IOException() // the original exception
                }
            }
        }
        try {
            inner.join()
        } catch (e: CancellationException) {
            println("Rethrowing CancellationException with original cause")
            throw e // cancellation exception is rethrown, yet the original IOException gets to the handler
        }
    }
    job.join()*/
    //endregion
}